<?xml version="1.0" encoding="utf-8"?>
<!-- This URDF was automatically created by SolidWorks to URDF Exporter! Originally created by Stephen Brawner (brawner@gmail.com) 
     Commit Version: 1.5.1-0-g916b5db  Build Version: 1.5.7152.31018
     For more information, please see http://wiki.ros.org/sw_urdf_exporter -->
<robot
  name="MAXILIFT">
  <link
    name="base_link">
    <inertial>
      <origin
        xyz="0.11407738258209 0.0150391052905878 0.369963764835343"
        rpy="0 0 0" />
      <mass
        value="7.62038215171722" />
      <inertia
        ixx="0.0644645456265057"
        ixy="0.00598814958694327"
        ixz="-5.8352096959931E-05"
        iyy="0.100370943555724"
        iyz="8.33184434949025E-09"
        izz="0.065229044638738" />
    </inertial>
    <visual>
      <origin
        xyz="0 0 0"
        rpy="0 0 0" />
      <geometry>
        <mesh
          filename="package://MAXILIFT/meshes/base_link.STL" />
      </geometry>
      <material
        name="">
        <color
          rgba="0.792156862745098 0.819607843137255 0.933333333333333 1" />
      </material>
    </visual>
    <collision>
      <origin
        xyz="0 0 0"
        rpy="0 0 0" />
      <geometry>
        <mesh
          filename="package://MAXILIFT/meshes/base_link.STL" />
      </geometry>
    </collision>
  </link>
  <link
    name="Vertical stand with beas">
    <inertial>
      <origin
        xyz="-0.0387732918568348 0.65718460966268 -2.30966837322377E-09"
        rpy="0 0 0" />
      <mass
        value="254.834380764319" />
      <inertia
        ixx="36.0056397351257"
        ixy="2.77957009849817"
        ixz="7.40295647005951E-09"
        iyy="1.28531486912778"
        iyz="-2.93407314333471E-07"
        izz="36.2286896654805" />
    </inertial>
    <visual>
      <origin
        xyz="0 0 0"
        rpy="0 0 0" />
      <geometry>
        <mesh
          filename="package://MAXILIFT/meshes/Vertical stand with beas.STL" />
      </geometry>
      <material
        name="">
        <color
          rgba="0.792156862745098 0.819607843137255 0.933333333333333 1" />
      </material>
    </visual>
    <collision>
      <origin
        xyz="0 0 0"
        rpy="0 0 0" />
      <geometry>
        <mesh
          filename="package://MAXILIFT/meshes/Vertical stand with beas.STL" />
      </geometry>
    </collision>
  </link>
  <joint
    name="rot1"
    type="revolute">
    <origin
      xyz="0.085308 -0.37046 0.034237"
      rpy="1.5708 0 -1.2041" />
    <parent
      link="base_link" />
    <child
      link="Vertical stand with beas" />
    <axis
      xyz="0 1 0" />
    <limit
      lower="0"
      upper="0"
      effort="0"
      velocity="0" />
  </joint>
  <link
    name="Vertical stand with V_piston">
    <inertial>
      <origin
        xyz="2.3318865388644E-07 0.422270415383065 -2.63032227110216E-08"
        rpy="0 0 0" />
      <mass
        value="3.66379019376401" />
      <inertia
        ixx="0.269331716594928"
        ixy="3.01217927505519E-08"
        ixz="9.63605696763237E-08"
        iyy="0.00671924319284911"
        iyz="-2.17052157475389E-08"
        izz="0.269210879612525" />
    </inertial>
    <visual>
      <origin
        xyz="0 0 0"
        rpy="0 0 0" />
      <geometry>
        <mesh
          filename="package://MAXILIFT/meshes/Vertical stand with V_piston.STL" />
      </geometry>
      <material
        name="">
        <color
          rgba="1 0 0 1" />
      </material>
    </visual>
    <collision>
      <origin
        xyz="0 0 0"
        rpy="0 0 0" />
      <geometry>
        <mesh
          filename="package://MAXILIFT/meshes/Vertical stand with V_piston.STL" />
      </geometry>
    </collision>
  </link>
  <joint
    name="rot 2"
    type="revolute">
    <origin
      xyz="0.14489 0.13172 0"
      rpy="3.0851 -1.5708 0" />
    <parent
      link="Vertical stand with beas" />
    <child
      link="Vertical stand with V_piston" />
    <axis
      xyz="1 0 0" />
    <limit
      lower="0"
      upper="0"
      effort="0"
      velocity="0" />
  </joint>
  <link
    name="V_piston with _ V_rod">
    <inertial>
      <origin
        xyz="-2.06316733142309E-09 0.380978346109326 7.14726577921709E-09"
        rpy="0 0 0" />
      <mass
        value="2.76307095410878" />
      <inertia
        ixx="0.135266919688303"
        ixy="1.41681768026403E-09"
        ixz="-1.2473976712668E-09"
        iyy="0.00161326448106642"
        iyz="-5.84216355297589E-09"
        izz="0.135247618162942" />
    </inertial>
    <visual>
      <origin
        xyz="0 0 0"
        rpy="0 0 0" />
      <geometry>
        <mesh
          filename="package://MAXILIFT/meshes/V_piston with _ V_rod.STL" />
      </geometry>
      <material
        name="">
        <color
          rgba="0.792156862745098 0.819607843137255 0.933333333333333 1" />
      </material>
    </visual>
    <collision>
      <origin
        xyz="0 0 0"
        rpy="0 0 0" />
      <geometry>
        <mesh
          filename="package://MAXILIFT/meshes/V_piston with _ V_rod.STL" />
      </geometry>
    </collision>
  </link>
  <joint
    name=" lin 1"
    type="continuous">
    <origin
      xyz="0 0.38281 0"
      rpy="0 0 0" />
    <parent
      link="Vertical stand with V_piston" />
    <child
      link="V_piston with _ V_rod" />
    <axis
      xyz="0 0.9984 0.056461" />
  </joint>
  <link
    name="V_rod with First level arm">
    <inertial>
      <origin
        xyz="-1.10458461613505E-08 -0.0013807032673816 0.564933698231049"
        rpy="0 0 0" />
      <mass
        value="16.9805251915454" />
      <inertia
        ixx="2.18258315258581"
        ixy="-4.81725956347212E-08"
        ixz="2.32757827907382E-08"
        iyy="2.17823021311207"
        iyz="-0.0240875595149625"
        izz="0.123944017728382" />
    </inertial>
    <visual>
      <origin
        xyz="0 0 0"
        rpy="0 0 0" />
      <geometry>
        <mesh
          filename="package://MAXILIFT/meshes/V_rod with First level arm.STL" />
      </geometry>
      <material
        name="">
        <color
          rgba="1 0 0 1" />
      </material>
    </visual>
    <collision>
      <origin
        xyz="0 0 0"
        rpy="0 0 0" />
      <geometry>
        <mesh
          filename="package://MAXILIFT/meshes/V_rod with First level arm.STL" />
      </geometry>
    </collision>
  </link>
  <joint
    name="rot 3"
    type="revolute">
    <origin
      xyz="0 0.93955 0.33325"
      rpy="-2.9305 0 -3.1416" />
    <parent
      link="V_piston with _ V_rod" />
    <child
      link="V_rod with First level arm" />
    <axis
      xyz="0 0 0" />
    <limit
      lower="0"
      upper="0"
      effort="0"
      velocity="0" />
  </joint>
  <link
    name="Vertical stand with First level arm">
    <inertial>
      <origin
        xyz="-1.10458461058394E-08 -0.0013807032673816 0.564933698231048"
        rpy="0 0 0" />
      <mass
        value="16.9805251915454" />
      <inertia
        ixx="2.18258315258582"
        ixy="-4.81725954404322E-08"
        ixz="2.32757832313579E-08"
        iyy="2.17823021311207"
        iyz="-0.0240875595149626"
        izz="0.123944017728382" />
    </inertial>
    <visual>
      <origin
        xyz="0 0 0"
        rpy="0 0 0" />
      <geometry>
        <mesh
          filename="package://MAXILIFT/meshes/Vertical stand with First level arm.STL" />
      </geometry>
      <material
        name="">
        <color
          rgba="1 0 0 1" />
      </material>
    </visual>
    <collision>
      <origin
        xyz="0 0 0"
        rpy="0 0 0" />
      <geometry>
        <mesh
          filename="package://MAXILIFT/meshes/Vertical stand with First level arm.STL" />
      </geometry>
    </collision>
  </link>
  <joint
    name="rot 4 "
    type="revolute">
    <origin
      xyz="0 1.3224 0.33325"
      rpy="-2.9305 0 -3.1416" />
    <parent
      link="Vertical stand with V_piston" />
    <child
      link="Vertical stand with First level arm" />
    <axis
      xyz="0 0 0" />
    <limit
      lower="0"
      upper="0"
      effort="0"
      velocity="0" />
  </joint>
  <link
    name="with First level arm with H_rod 1">
    <inertial>
      <origin
        xyz="-0.0931801799459544 0.587021892552616 -0.00786332251854832"
        rpy="0 0 0" />
      <mass
        value="5.03365199309053" />
      <inertia
        ixx="0.598236292424871"
        ixy="0.00184896963412509"
        ixz="3.4235697976278E-05"
        iyy="0.0203097339720695"
        iyz="0.00321400282175937"
        izz="0.595493912216817" />
    </inertial>
    <visual>
      <origin
        xyz="0 0 0"
        rpy="0 0 0" />
      <geometry>
        <mesh
          filename="package://MAXILIFT/meshes/with First level arm with H_rod 1.STL" />
      </geometry>
      <material
        name="">
        <color
          rgba="0.792156862745098 0.819607843137255 0.933333333333333 1" />
      </material>
    </visual>
    <collision>
      <origin
        xyz="0 0 0"
        rpy="0 0 0" />
      <geometry>
        <mesh
          filename="package://MAXILIFT/meshes/with First level arm with H_rod 1.STL" />
      </geometry>
    </collision>
  </link>
  <joint
    name="lin 2"
    type="continuous">
    <origin
      xyz="0 0.0985 1.1678"
      rpy="1.5708 0 1.5708" />
    <parent
      link="Vertical stand with First level arm" />
    <child
      link="with First level arm with H_rod 1" />
    <axis
      xyz="0 1 0" />
    <limit
      lower="-1"
      upper="0"
      effort="0"
      velocity="0" />
  </joint>
  <link
    name="H_rod with 2 First level arm">
    <inertial>
      <origin
        xyz="0.605322024472593 -0.0083759328527433 -0.000754591032865237"
        rpy="0 0 0" />
      <mass
        value="4.72559099416961" />
      <inertia
        ixx="0.0202958149305245"
        ixy="0.00321400451244405"
        ixz="0.00184897116063022"
        iyy="0.565146065709871"
        iyz="3.42356399018438E-05"
        izz="0.567888481715816" />
    </inertial>
    <visual>
      <origin
        xyz="0 0 0"
        rpy="0 0 0" />
      <geometry>
        <mesh
          filename="package://MAXILIFT/meshes/H_rod with 2 First level arm.STL" />
      </geometry>
      <material
        name="">
        <color
          rgba="1 0 0 1" />
      </material>
    </visual>
    <collision>
      <origin
        xyz="0 0 0"
        rpy="0 0 0" />
      <geometry>
        <mesh
          filename="package://MAXILIFT/meshes/H_rod with 2 First level arm.STL" />
      </geometry>
    </collision>
  </link>
  <joint
    name="lin 5"
    type="continuous">
    <origin
      xyz="-0.0985 -0.014294 0"
      rpy="1.5708 0 1.5708" />
    <parent
      link="with First level arm with H_rod 1" />
    <child
      link="H_rod with 2 First level arm" />
    <axis
      xyz="0 0 0" />
  </joint>
  <link
    name="with First level arm with 2 level arm">
    <inertial>
      <origin
        xyz="0.605322024472596 -0.0083759328527433 -0.000754591032865459"
        rpy="0 0 0" />
      <mass
        value="4.7255909941696" />
      <inertia
        ixx="0.0202958149305246"
        ixy="0.00321400451244474"
        ixz="0.00184897116063037"
        iyy="0.565146065709873"
        iyz="3.42356399018855E-05"
        izz="0.567888481715818" />
    </inertial>
    <visual>
      <origin
        xyz="0 0 0"
        rpy="0 0 0" />
      <geometry>
        <mesh
          filename="package://MAXILIFT/meshes/with First level arm with 2 level arm.STL" />
      </geometry>
      <material
        name="">
        <color
          rgba="1 0 0 1" />
      </material>
    </visual>
    <collision>
      <origin
        xyz="0 0 0"
        rpy="0 0 0" />
      <geometry>
        <mesh
          filename="package://MAXILIFT/meshes/with First level arm with 2 level arm.STL" />
      </geometry>
    </collision>
  </link>
  <joint
    name="lin3"
    type="continuous">
    <origin
      xyz="0 0 1.1535"
      rpy="1.5708 -1.5708 0" />
    <parent
      link="Vertical stand with First level arm" />
    <child
      link="with First level arm with 2 level arm" />
    <axis
      xyz="0 0 0" />
  </joint>
  <link
    name="2 level arm with H_rod 2">
    <inertial>
      <origin
        xyz="-5.28709633851321E-08 0.473238235488486 -1.55914479105235E-08"
        rpy="0 0 0" />
      <mass
        value="0.308440194023462" />
      <inertia
        ixx="0.0304589076111692"
        ixy="6.87591625956708E-09"
        ixz="6.4868018725614E-11"
        iyy="1.39377992666822E-05"
        iyz="2.2148334627778E-09"
        izz="0.0304589465374647" />
    </inertial>
    <visual>
      <origin
        xyz="0 0 0"
        rpy="0 0 0" />
      <geometry>
        <mesh
          filename="package://MAXILIFT/meshes/2 level arm with H_rod 2.STL" />
      </geometry>
      <material
        name="">
        <color
          rgba="0.792156862745098 0.819607843137255 0.933333333333333 1" />
      </material>
    </visual>
    <collision>
      <origin
        xyz="0 0 0"
        rpy="0 0 0" />
      <geometry>
        <mesh
          filename="package://MAXILIFT/meshes/2 level arm with H_rod 2.STL" />
      </geometry>
    </collision>
  </link>
  <joint
    name="lin 5"
    type="continuous">
    <origin
      xyz="1.0698 -0.1062 0"
      rpy="3.1416 0 1.5708" />
    <parent
      link="with First level arm with 2 level arm" />
    <child
      link="2 level arm with H_rod 2" />
    <axis
      xyz="0 1 0" />
    <limit
      lower="-0.949"
      upper="0"
      effort="0"
      velocity="0" />
  </joint>
  <link
    name="H-rod 2 with 2 level arm">
    <inertial>
      <origin
        xyz="0.558002375272954 -0.000898725132921996 0.000106213561132829"
        rpy="0 0 0" />
      <mass
        value="10.0005340407947" />
      <inertia
        ixx="0.01547220448355"
        ixy="0.00470984559889654"
        ixz="-0.00163602543594855"
        iyy="1.0427878679906"
        iyz="-9.59045414250514E-07"
        izz="1.04338216018405" />
    </inertial>
    <visual>
      <origin
        xyz="0 0 0"
        rpy="0 0 0" />
      <geometry>
        <mesh
          filename="package://MAXILIFT/meshes/H-rod 2 with 2 level arm.STL" />
      </geometry>
      <material
        name="">
        <color
          rgba="0.694117647058824 0.0980392156862745 0.0980392156862745 1" />
      </material>
    </visual>
    <collision>
      <origin
        xyz="0 0 0"
        rpy="0 0 0" />
      <geometry>
        <mesh
          filename="package://MAXILIFT/meshes/H-rod 2 with 2 level arm.STL" />
      </geometry>
    </collision>
  </link>
  <joint
    name="lin7"
    type="continuous">
    <origin
      xyz="0.1062 -0.073292 0"
      rpy="-1.5708 0 1.5708" />
    <parent
      link="2 level arm with H_rod 2" />
    <child
      link="H-rod 2 with 2 level arm" />
    <axis
      xyz="0 0 0" />
  </joint>
  <link
    name="2 level arm with 3level arm">
    <inertial>
      <origin
        xyz="0.558002375272959 -0.000898725132921552 0.000106213561132273"
        rpy="0 0 0" />
      <mass
        value="10.0005340407947" />
      <inertia
        ixx="0.0154722044835498"
        ixy="0.0047098455988957"
        ixz="-0.00163602543594822"
        iyy="1.04278786799059"
        iyz="-9.59045414271331E-07"
        izz="1.04338216018404" />
    </inertial>
    <visual>
      <origin
        xyz="0 0 0"
        rpy="0 0 0" />
      <geometry>
        <mesh
          filename="package://MAXILIFT/meshes/2 level arm with 3level arm.STL" />
      </geometry>
      <material
        name="">
        <color
          rgba="0.694117647058824 0.0980392156862745 0.0980392156862745 1" />
      </material>
    </visual>
    <collision>
      <origin
        xyz="0 0 0"
        rpy="0 0 0" />
      <geometry>
        <mesh
          filename="package://MAXILIFT/meshes/2 level arm with 3level arm.STL" />
      </geometry>
    </collision>
  </link>
  <joint
    name="lin6"
    type="continuous">
    <origin
      xyz="0.9965 0 0"
      rpy="1.5708 0 0" />
    <parent
      link="with First level arm with 2 level arm" />
    <child
      link="2 level arm with 3level arm" />
    <axis
      xyz="0 0 0" />
  </joint>
  <link
    name="3  level arm with hook">
    <inertial>
      <origin
        xyz="0.0402400456416623 -0.0967879498833805 -5.78917880909025E-05"
        rpy="0 0 0" />
      <mass
        value="0.264834723337005" />
      <inertia
        ixx="0.000487667739325346"
        ixy="0.000274708960386294"
        ixz="-7.81961840354384E-07"
        iyy="0.000525138802079056"
        iyz="-7.80562268489529E-07"
        izz="0.000966801609865548" />
    </inertial>
    <visual>
      <origin
        xyz="0 0 0"
        rpy="0 0 0" />
      <geometry>
        <mesh
          filename="package://MAXILIFT/meshes/3  level arm with hook.STL" />
      </geometry>
      <material
        name="">
        <color
          rgba="0.792156862745098 0.819607843137255 0.933333333333333 1" />
      </material>
    </visual>
    <collision>
      <origin
        xyz="0 0 0"
        rpy="0 0 0" />
      <geometry>
        <mesh
          filename="package://MAXILIFT/meshes/3  level arm with hook.STL" />
      </geometry>
    </collision>
  </link>
  <joint
    name="rot 7"
    type="revolute">
    <origin
      xyz="1.0825 -0.119 0"
      rpy="0 0 0.40305" />
    <parent
      link="2 level arm with 3level arm" />
    <child
      link="3  level arm with hook" />
    <axis
      xyz="0 0 1" />
    <limit
      lower="0"
      upper="0"
      effort="0"
      velocity="0" />
  </joint>
</robot>